Workbook

Sheet JANUARY 10, 2026
B1: TOTAL PRICE OF ITEMS: | C1: =SUM('JANUARY 10, 2026'!$G$4:$G$1189) -> 0 | D1: HIGHEST PRICE: | E1: =MAX('JANUARY 10, 2026'!$G$4:$G$1189) -> 0 | F1: NUMBER OF ITEMS | G1: =COUNT('JANUARY 10, 2026'!$G$4:$G$1189) -> 0 | I1: =CONCATENATE("P"," ",SUMIF('JANUARY 10, 2026'!$E$4:$E$1189,H1,'JANUARY 10, 2026'!$G$4:$G$1189)) -> P 0 | J1: =CONCATENATE(COUNTIF('JANUARY 10, 2026'!$E$4:$E$1189,H1)," ","PCS") -> 0 PCS | L1: =COUNT(L4:L1079) -> 0
D2: MONITORING
A3: 1 | B3: BARCODE | C3: CONTROL # | D3: DESCRIPTION | E3: BIDDER # | F3: QTY | G3: PRICE | H3: MANIFEST NUMBER | I3: REMARKS | J3: DATE | K3: REFUND | L3: BIDDERS
A4: =LEFT('JANUARY 10, 2026'!$E9,FIND("-",'JANUARY 10, 2026'!$E9&"-")-1)
A5: =LEFT('JANUARY 10, 2026'!$E10,FIND("-",'JANUARY 10, 2026'!$E10&"-")-1)
A6: =LEFT('JANUARY 10, 2026'!$E125,FIND("-",'JANUARY 10, 2026'!$E125&"-")-1)
A7: =LEFT('JANUARY 10, 2026'!#REF!,FIND("-",'JANUARY 10, 2026'!#REF!&"-")-1) -> #ERROR!
A8: =LEFT('JANUARY 10, 2026'!$E5,FIND("-",'JANUARY 10, 2026'!$E5&"-")-1)
A9: =LEFT('JANUARY 10, 2026'!$E6,FIND("-",'JANUARY 10, 2026'!$E6&"-")-1)
A10: =LEFT('JANUARY 10, 2026'!#REF!,FIND("-",'JANUARY 10, 2026'!#REF!&"-")-1) -> #ERROR!
A11: =LEFT('JANUARY 10, 2026'!$E7,FIND("-",'JANUARY 10, 2026'!$E7&"-")-1)
A12: =LEFT('JANUARY 10, 2026'!$E8,FIND("-",'JANUARY 10, 2026'!$E8&"-")-1)
A13: =LEFT('JANUARY 10, 2026'!$E11,FIND("-",'JANUARY 10, 2026'!$E11&"-")-1)
A14: =LEFT('JANUARY 10, 2026'!$E12,FIND("-",'JANUARY 10, 2026'!$E12&"-")-1)
A15: =LEFT('JANUARY 10, 2026'!$E13,FIND("-",'JANUARY 10, 2026'!$E13&"-")-1)
A16: =LEFT('JANUARY 10, 2026'!$E14,FIND("-",'JANUARY 10, 2026'!$E14&"-")-1)
A17: =LEFT('JANUARY 10, 2026'!$E15,FIND("-",'JANUARY 10, 2026'!$E15&"-")-1)
A18: =LEFT('JANUARY 10, 2026'!$E16,FIND("-",'JANUARY 10, 2026'!$E16&"-")-1)
A19: =LEFT('JANUARY 10, 2026'!$E17,FIND("-",'JANUARY 10, 2026'!$E17&"-")-1)
A20: =LEFT('JANUARY 10, 2026'!$E18,FIND("-",'JANUARY 10, 2026'!$E18&"-")-1)
A21: =LEFT('JANUARY 10, 2026'!$E19,FIND("-",'JANUARY 10, 2026'!$E19&"-")-1)
A22: =LEFT('JANUARY 10, 2026'!$E20,FIND("-",'JANUARY 10, 2026'!$E20&"-")-1)
A23: =LEFT('JANUARY 10, 2026'!$E21,FIND("-",'JANUARY 10, 2026'!$E21&"-")-1)
A24: =LEFT('JANUARY 10, 2026'!$E22,FIND("-",'JANUARY 10, 2026'!$E22&"-")-1)
... A126: =LEFT('JANUARY 10, 2026'!$E124,FIND("-",'JANUARY 10, 2026'!$E124&"-")-1)
A127: =LEFT('JANUARY 10, 2026'!$E126,FIND("-",'JANUARY 10, 2026'!$E126&"-")-1)
A128: =LEFT('JANUARY 10, 2026'!$E4,FIND("-",'JANUARY 10, 2026'!$E4&"-")-1)
A129: =LEFT('JANUARY 10, 2026'!$E128,FIND("-",'JANUARY 10, 2026'!$E128&"-")-1)
A130: =LEFT('JANUARY 10, 2026'!$E129,FIND("-",'JANUARY 10, 2026'!$E129&"-")-1)
A131: =LEFT('JANUARY 10, 2026'!$E130,FIND("-",'JANUARY 10, 2026'!$E130&"-")-1)
A132: =LEFT('JANUARY 10, 2026'!$E131,FIND("-",'JANUARY 10, 2026'!$E131&"-")-1)
A133: =LEFT('JANUARY 10, 2026'!$E132,FIND("-",'JANUARY 10, 2026'!$E132&"-")-1)
A134: =LEFT('JANUARY 10, 2026'!$E133,FIND("-",'JANUARY 10, 2026'!$E133&"-")-1)
A294: =LEFT('[1]DECEMBER 13, 2025'!$E86,FIND("-",'[1]DECEMBER 13, 2025'!$E86&"-")-1) -> #REF!
A295: =LEFT('[1]DECEMBER 13, 2025'!$E87,FIND("-",'[1]DECEMBER 13, 2025'!$E87&"-")-1) -> #REF!
A296: =LEFT('[1]DECEMBER 13, 2025'!$E88,FIND("-",'[1]DECEMBER 13, 2025'!$E88&"-")-1) -> #REF!
A297: =LEFT('[1]DECEMBER 13, 2025'!$E89,FIND("-",'[1]DECEMBER 13, 2025'!$E89&"-")-1) -> #REF!
A298: =LEFT('[1]DECEMBER 13, 2025'!$E90,FIND("-",'[1]DECEMBER 13, 2025'!$E90&"-")-1) -> #REF!
A299: =LEFT('[1]DECEMBER 13, 2025'!$E91,FIND("-",'[1]DECEMBER 13, 2025'!$E91&"-")-1) -> #REF!
A300: =LEFT('[1]DECEMBER 13, 2025'!$E92,FIND("-",'[1]DECEMBER 13, 2025'!$E92&"-")-1) -> #REF!
...

Sheet BIÑAN INFO
A1: BIDDER NUMBER | D1: BIDDER INFORMATION | I1: 0.05 | J1: REGISTRATION
A2: PALA-PALA BRANCH | B2: BIÑAN BRANCH | C2: BACOOR BRANCH | D2: FULL NAME | E2: FIRST NAME | F2: MIDDLE NAME | G2: LAST NAME | H2: INITIALS / OTHERS | I2: 12% | J2: FEE | K2: DOCUMENTS SUBMITTED | L2: MONTH | M2: EXPIRED DATE | N2: REMARKS
B3: 0 | D3: =CONCATENATE(PROPER('BIÑAN INFO'!$G3),", ",PROPER('BIÑAN INFO'!$E3)," ",PROPER('BIÑAN INFO'!$F3),"."," (",UPPER('BIÑAN INFO'!$H3),")") -> Biñan, Ren-A-Mark . () | E3: REN-A-MARK | G3: BIÑAN | I3: 0
B4: 1 | D4: =CONCATENATE(PROPER('BIÑAN INFO'!$G4),", ",PROPER('BIÑAN INFO'!$E4)," ",PROPER('BIÑAN INFO'!$F4),"."," (",UPPER('BIÑAN INFO'!$H4),")") -> , . () | I4: 0.12 | J4: 1000
B5: 2 | D5: =CONCATENATE(PROPER('BIÑAN INFO'!$G5),", ",PROPER('BIÑAN INFO'!$E5)," ",PROPER('BIÑAN INFO'!$F5),"."," (",UPPER('BIÑAN INFO'!$H5),")") -> , . () | I5: 0.05 | J5: 1000
B6: 3 | D6: =CONCATENATE(PROPER('BIÑAN INFO'!$G6),", ",PROPER('BIÑAN INFO'!$E6)," ",PROPER('BIÑAN INFO'!$F6),"."," (",UPPER('BIÑAN INFO'!$H6),")") -> , . () | I6: 0.12 | J6: 1000
B7: 7 | D7: =CONCATENATE(PROPER('BIÑAN INFO'!$G7),", ",PROPER('BIÑAN INFO'!$E7)," ",PROPER('BIÑAN INFO'!$F7),"."," (",UPPER('BIÑAN INFO'!$H7),")") -> , . () | I7: 0.05 | J7: 1000 | M7: 2021
B8: 8 | D8: =CONCATENATE(PROPER('BIÑAN INFO'!$G8),", ",PROPER('BIÑAN INFO'!$E8)," ",PROPER('BIÑAN INFO'!$F8),"."," (",UPPER('BIÑAN INFO'!$H8),")") -> Mabeza, Joana . () | E8: JOANA | G8: MABEZA | I8: 0.05 | J8: 1000
B9: 9 | D9: =CONCATENATE(PROPER('BIÑAN INFO'!$G9),", ",PROPER('BIÑAN INFO'!$E9)," ",PROPER('BIÑAN INFO'!$F9),"."," (",UPPER('BIÑAN INFO'!$H9),")") -> , . () | I9: 0.12 | J9: 1000
B10: 10 | D10: =CONCATENATE(PROPER('BIÑAN INFO'!$G10),", ",PROPER('BIÑAN INFO'!$E10)," ",PROPER('BIÑAN INFO'!$F10),"."," (",UPPER('BIÑAN INFO'!$H10),")") -> Bedia, Edward . () | E10: EDWARD | G10: BEDIA | I10: 0.12 | J10: 1000
B11: 11 | D11: =CONCATENATE(PROPER('BIÑAN INFO'!$G11),", ",PROPER('BIÑAN INFO'!$E11)," ",PROPER('BIÑAN INFO'!$F11),"."," (",UPPER('BIÑAN INFO'!$H11),")") -> , . () | I11: 0.12 | J11: 1000
B12: 12 | D12: =CONCATENATE(PROPER('BIÑAN INFO'!$G12),", ",PROPER('BIÑAN INFO'!$E12)," ",PROPER('BIÑAN INFO'!$F12),"."," (",UPPER('BIÑAN INFO'!$H12),")") -> , . () | I12: 0.12 | J12: 1000
B13: 13 | D13: =CONCATENATE(PROPER('BIÑAN INFO'!$G13),", ",PROPER('BIÑAN INFO'!$E13)," ",PROPER('BIÑAN INFO'!$F13),"."," (",UPPER('BIÑAN INFO'!$H13),")") -> Bascon, Michael . () | E13: MICHAEL | G13: BASCON | I13: 0.12 | J13: 1000
B14: 14 | D14: =CONCATENATE(PROPER('BIÑAN INFO'!$G14),", ",PROPER('BIÑAN INFO'!$E14)," ",PROPER('BIÑAN INFO'!$F14),"."," (",UPPER('BIÑAN INFO'!$H14),")") -> Yatco, Neptaly . () | E14: NEPTALY | G14: YATCO | I14: 0.05 | J14: 1000
B15: 15 | D15: =CONCATENATE(PROPER('BIÑAN INFO'!$G15),", ",PROPER('BIÑAN INFO'!$E15)," ",PROPER('BIÑAN INFO'!$F15),"."," (",UPPER('BIÑAN INFO'!$H15),")") -> , . () | I15: 0.12 | J15: 1000
B16: 16 | D16: =CONCATENATE(PROPER('BIÑAN INFO'!$G16),", ",PROPER('BIÑAN INFO'!$E16)," ",PROPER('BIÑAN INFO'!$F16),"."," (",UPPER('BIÑAN INFO'!$H16),")") -> , . () | I16: 0.12 | J16: 1000
B17: 17 | D17: =CONCATENATE(PROPER('BIÑAN INFO'!$G17),", ",PROPER('BIÑAN INFO'!$E17)," ",PROPER('BIÑAN INFO'!$F17),"."," (",UPPER('BIÑAN INFO'!$H17),")") -> , . () | I17: 0.12 | J17: 1000
B18: 18 | D18: =CONCATENATE(PROPER('BIÑAN INFO'!$G18),", ",PROPER('BIÑAN INFO'!$E18)," ",PROPER('BIÑAN INFO'!$F18),"."," (",UPPER('BIÑAN INFO'!$H18),")") -> , . () | I18: 0.12 | J18: 1000
B19: 19 | D19: =CONCATENATE(PROPER('BIÑAN INFO'!$G19),", ",PROPER('BIÑAN INFO'!$E19)," ",PROPER('BIÑAN INFO'!$F19),"."," (",UPPER('BIÑAN INFO'!$H19),")") -> Cano, Rosemarie . () | E19: ROSEMARIE | G19: CANO | I19: 0.05 | J19: 1000
B20: 20 | D20: =CONCATENATE(PROPER('BIÑAN INFO'!$G20),", ",PROPER('BIÑAN INFO'!$E20)," ",PROPER('BIÑAN INFO'!$F20),"."," (",UPPER('BIÑAN INFO'!$H20),")") -> Malayan, Sonny . () | E20: SONNY | G20: MALAYAN | I20: 0.12 | J20: 1000
B21: 21 | D21: =CONCATENATE(PROPER('BIÑAN INFO'!$G21),", ",PROPER('BIÑAN INFO'!$E21)," ",PROPER('BIÑAN INFO'!$F21),"."," (",UPPER('BIÑAN INFO'!$H21),")") -> , . () | I21: 0.12 | J21: 1000
B22: 22 | D22: =CONCATENATE(PROPER('BIÑAN INFO'!$G22),", ",PROPER('BIÑAN INFO'!$E22)," ",PROPER('BIÑAN INFO'!$F22),"."," (",UPPER('BIÑAN INFO'!$H22),")") -> , . () | I22: 0.12 | J22: 1000
B23: 23 | D23: =CONCATENATE(PROPER('BIÑAN INFO'!$G23),", ",PROPER('BIÑAN INFO'!$E23)," ",PROPER('BIÑAN INFO'!$F23),"."," (",UPPER('BIÑAN INFO'!$H23),")") -> , . () | I23: 0.12 | J23: 1000
B24: 24 | D24: =CONCATENATE(PROPER('BIÑAN INFO'!$G24),", ",PROPER('BIÑAN INFO'!$E24)," ",PROPER('BIÑAN INFO'!$F24),"."," (",UPPER('BIÑAN INFO'!$H24),")") -> , . () | I24: 0.12 | J24: 1000
B25: 25 | D25: =CONCATENATE(PROPER('BIÑAN INFO'!$G25),", ",PROPER('BIÑAN INFO'!$E25)," ",PROPER('BIÑAN INFO'!$F25),"."," (",UPPER('BIÑAN INFO'!$H25),")") -> , . () | I25: 0.12 | J25: 1000
B26: 26 | D26: =CONCATENATE(PROPER('BIÑAN INFO'!$G26),", ",PROPER('BIÑAN INFO'!$E26)," ",PROPER('BIÑAN INFO'!$F26),"."," (",UPPER('BIÑAN INFO'!$H26),")") -> Banes, Irene . () | E26: IRENE | G26: BANES | I26: 0.12 | J26: 1000
B27: 27 | D27: =CONCATENATE(PROPER('BIÑAN INFO'!$G27),", ",PROPER('BIÑAN INFO'!$E27)," ",PROPER('BIÑAN INFO'!$F27),"."," (",UPPER('BIÑAN INFO'!$H27),")") -> , . () | I27: 0.12 | J27: 1000
B28: 28 | D28: =CONCATENATE(PROPER('BIÑAN INFO'!$G28),", ",PROPER('BIÑAN INFO'!$E28)," ",PROPER('BIÑAN INFO'!$F28),"."," (",UPPER('BIÑAN INFO'!$H28),")") -> , . () | I28: 0.12 | J28: 1000
B29: 29 | D29: =CONCATENATE(PROPER('BIÑAN INFO'!$G29),", ",PROPER('BIÑAN INFO'!$E29)," ",PROPER('BIÑAN INFO'!$F29),"."," (",UPPER('BIÑAN INFO'!$H29),")") -> , . () | I29: 0.12 | J29: 1000
B30: 30 | D30: =CONCATENATE(PROPER('BIÑAN INFO'!$G30),", ",PROPER('BIÑAN INFO'!$E30)," ",PROPER('BIÑAN INFO'!$F30),"."," (",UPPER('BIÑAN INFO'!$H30),")") -> , . () | I30: 0.12 | J30: 1000
B31: 31 | D31: =CONCATENATE(PROPER('BIÑAN INFO'!$G31),", ",PROPER('BIÑAN INFO'!$E31)," ",PROPER('BIÑAN INFO'!$F31),"."," (",UPPER('BIÑAN INFO'!$H31),")") -> , . () | I31: 0.12 | J31: 1000
B32: 32 | D32: =CONCATENATE(PROPER('BIÑAN INFO'!$G32),", ",PROPER('BIÑAN INFO'!$E32)," ",PROPER('BIÑAN INFO'!$F32),"."," (",UPPER('BIÑAN INFO'!$H32),")") -> Villadiego, Ma. Lourdes . () | E32: MA. LOURDES | G32: VILLADIEGO | I32: 0.05 | J32: 1000 | K32: DTI
B33: 33 | D33: =CONCATENATE(PROPER('BIÑAN INFO'!$G33),", ",PROPER('BIÑAN INFO'!$E33)," ",PROPER('BIÑAN INFO'!$F33),"."," (",UPPER('BIÑAN INFO'!$H33),")") -> , . () | I33: 0.12 | J33: 1000
B34: 34 | D34: =CONCATENATE(PROPER('BIÑAN INFO'!$G34),", ",PROPER('BIÑAN INFO'!$E34)," ",PROPER('BIÑAN INFO'!$F34),"."," (",UPPER('BIÑAN INFO'!$H34),")") -> , . () | I34: 0.12 | J34: 1000
B35: 35 | D35: =CONCATENATE(PROPER('BIÑAN INFO'!$G35),", ",PROPER('BIÑAN INFO'!$E35)," ",PROPER('BIÑAN INFO'!$F35),"."," (",UPPER('BIÑAN INFO'!$H35),")") -> , . () | I35: 0.12 | J35: 1000
B36: 36 | D36: =CONCATENATE(PROPER('BIÑAN INFO'!$G36),", ",PROPER('BIÑAN INFO'!$E36)," ",PROPER('BIÑAN INFO'!$F36),"."," (",UPPER('BIÑAN INFO'!$H36),")") -> , . () | I36: 0.12 | J36: 1000
B37: 37 | D37: =CONCATENATE(PROPER('BIÑAN INFO'!$G37),", ",PROPER('BIÑAN INFO'!$E37)," ",PROPER('BIÑAN INFO'!$F37),"."," (",UPPER('BIÑAN INFO'!$H37),")") -> , . () | I37: 0.12 | J37: 1000
B38: 38 | D38: =CONCATENATE(PROPER('BIÑAN INFO'!$G38),", ",PROPER('BIÑAN INFO'!$E38)," ",PROPER('BIÑAN INFO'!$F38),"."," (",UPPER('BIÑAN INFO'!$H38),")") -> Lorenzana, Naneth . () | E38: NANETH | G38: LORENZANA | I38: 0.05 | J38: 1000
B39: 39 | D39: =CONCATENATE(PROPER('BIÑAN INFO'!$G39),", ",PROPER('BIÑAN INFO'!$E39)," ",PROPER('BIÑAN INFO'!$F39),"."," (",UPPER('BIÑAN INFO'!$H39),")") -> , . () | I39: 0.12 | J39: 1000
B40: 40 | D40: =CONCATENATE(PROPER('BIÑAN INFO'!$G40),", ",PROPER('BIÑAN INFO'!$E40)," ",PROPER('BIÑAN INFO'!$F40),"."," (",UPPER('BIÑAN INFO'!$H40),")") -> , . () | I40: 0.12 | J40: 1000
...

Sheet DASMA INFO
A1: BIDDER NUMBER | D1: BIDDER INFORMATION | I1: 0.05 | J1: REGISTRATION
A2: PALA-PALA BRANCH | B2: BIÑAN BRANCH | C2: BACOOR BRANCH | D2: FULL NAME | E2: FIRST NAME | F2: MIDDLE NAME | G2: LAST NAME | H2: INITIALS / OTHERS | I2: 12% | J2: FEE | K2: DOCUMENTS SUBMITTED | L2: MONTH | M2: EXPIRED DATE | N2: REMARKS
A3: 0 | D3: =CONCATENATE(PROPER('DASMA INFO'!$G3),", ",PROPER('DASMA INFO'!$E3)," ",PROPER('DASMA INFO'!$F3),"."," (",UPPER('DASMA INFO'!$H3),")") -> Ren A Mark, Dasma Branch. () | E3: DASMA | F3: BRANCH | G3: REN A MARK
A4: 1 | D4: =CONCATENATE(PROPER('DASMA INFO'!$G4),", ",PROPER('DASMA INFO'!$E4)," ",PROPER('DASMA INFO'!$F4),"."," (",UPPER('DASMA INFO'!$H4),")") -> Mesina, Emmanuel A. () | E4: EMMANUEL | F4: A | G4: MESINA | I4: 0.05 | J4: 1000 | K4: DRIVER'S LICENSE ID, OTHER ID
A5: 2 | D5: =CONCATENATE(PROPER('DASMA INFO'!$G5),", ",PROPER('DASMA INFO'!$E5)," ",PROPER('DASMA INFO'!$F5),"."," (",UPPER('DASMA INFO'!$H5),")") -> Saladar, Nido . () | E5: NIDO | G5: SALADAR | I5: 0.05 | J5: 1000
A6: 3 | D6: =CONCATENATE(PROPER('DASMA INFO'!$G6),", ",PROPER('DASMA INFO'!$E6)," ",PROPER('DASMA INFO'!$F6),"."," (",UPPER('DASMA INFO'!$H6),")") -> Alcuaran, Pablito . () | E6: PABLITO | G6: ALCUARAN | I6: 0.05 | J6: 1000
A7: 7 | D7: =CONCATENATE(PROPER('DASMA INFO'!$G7),", ",PROPER('DASMA INFO'!$E7)," ",PROPER('DASMA INFO'!$F7),"."," (",UPPER('DASMA INFO'!$H7),")") -> Bermundo, Leandro Jivan C. () | E7: LEANDRO JIVAN | F7: C | G7: BERMUNDO | I7: 0.05 | J7: 1000 | K7: VOTER'S ID
A8: 8 | D8: =CONCATENATE(PROPER('DASMA INFO'!$G8),", ",PROPER('DASMA INFO'!$E8)," ",PROPER('DASMA INFO'!$F8),"."," (",UPPER('DASMA INFO'!$H8),")") -> Pastorpide, Yolanda S. () | E8: YOLANDA | F8: S | G8: PASTORPIDE | I8: 0.05 | J8: 1000 | K8: UNIFIED MULTI-PURPOSE ID
A9: 9 | D9: =CONCATENATE(PROPER('DASMA INFO'!$G9),", ",PROPER('DASMA INFO'!$E9)," ",PROPER('DASMA INFO'!$F9),"."," (",UPPER('DASMA INFO'!$H9),")") -> Mabansag, Jennifer . () | E9: JENNIFER | G9: MABANSAG | I9: 0.05 | J9: 1000
A10: 10 | D10: =CONCATENATE(PROPER('DASMA INFO'!$G10),", ",PROPER('DASMA INFO'!$E10)," ",PROPER('DASMA INFO'!$F10),"."," (",UPPER('DASMA INFO'!$H10),")") -> Ogang, Ester . () | E10: ESTER | G10: OGANG | I10: 0.05 | J10: 1000
A11: 11 | D11: =CONCATENATE(PROPER('DASMA INFO'!$G11),", ",PROPER('DASMA INFO'!$E11)," ",PROPER('DASMA INFO'!$F11),"."," (",UPPER('DASMA INFO'!$H11),")") -> Bermudo, Lenny S. () | E11: LENNY | F11: S | G11: BERMUDO | I11: 0.05 | J11: 1000 | K11: DRIVER'S LICENSE ID
A12: 12 | D12: =CONCATENATE(PROPER('DASMA INFO'!$G12),", ",PROPER('DASMA INFO'!$E12)," ",PROPER('DASMA INFO'!$F12),"."," (",UPPER('DASMA INFO'!$H12),")") -> Cruz, Norlyn . () | E12: NORLYN | G12: CRUZ | I12: 0.05 | J12: 1000
A13: 13 | D13: =CONCATENATE(PROPER('DASMA INFO'!$G13),", ",PROPER('DASMA INFO'!$E13)," ",PROPER('DASMA INFO'!$F13),"."," (",UPPER('DASMA INFO'!$H13),")") -> Conde, Jennelyn . () | E13: JENNELYN | G13: CONDE | I13: 0.05 | J13: 1000
A14: 14 | D14: =CONCATENATE(PROPER('DASMA INFO'!$G14),", ",PROPER('DASMA INFO'!$E14)," ",PROPER('DASMA INFO'!$F14),"."," (",UPPER('DASMA INFO'!$H14),")") -> Vianzon, Laurice . () | E14: LAURICE | G14: VIANZON | I14: 0.05 | J14: 1000
A15: 15 | D15: =CONCATENATE(PROPER('DASMA INFO'!$G15),", ",PROPER('DASMA INFO'!$E15)," ",PROPER('DASMA INFO'!$F15),"."," (",UPPER('DASMA INFO'!$H15),")") -> Ting, Alberto . () | E15: ALBERTO | G15: TING | I15: 0.05 | J15: 1000
A16: 16 | D16: =CONCATENATE(PROPER('DASMA INFO'!$G16),", ",PROPER('DASMA INFO'!$E16)," ",PROPER('DASMA INFO'!$F16),"."," (",UPPER('DASMA INFO'!$H16),")") -> Alberto, Shiela . () | E16: SHIELA | G16: ALBERTO | I16: 0.05 | J16: 1000
A17: 17 | D17: =CONCATENATE(PROPER('DASMA INFO'!$G17),", ",PROPER('DASMA INFO'!$E17)," ",PROPER('DASMA INFO'!$F17),"."," (",UPPER('DASMA INFO'!$H17),")") -> Liliman, Lutgarda . () | E17: LUTGARDA | G17: LILIMAN | I17: 0.05 | J17: 1000
A18: 18 | D18: =CONCATENATE(PROPER('DASMA INFO'!$G18),", ",PROPER('DASMA INFO'!$E18)," ",PROPER('DASMA INFO'!$F18),"."," (",UPPER('DASMA INFO'!$H18),")") -> Conde, Rommel . () | E18: ROMMEL | G18: CONDE | I18: 0.05 | J18: 1000
A19: 19 | D19: =CONCATENATE(PROPER('DASMA INFO'!$G19),", ",PROPER('DASMA INFO'!$E19)," ",PROPER('DASMA INFO'!$F19),"."," (",UPPER('DASMA INFO'!$H19),")") -> Hidalgo, Rodolfo P. () | E19: RODOLFO | F19: P | G19: HIDALGO | I19: 0.05 | J19: 1000
A20: 20 | D20: =CONCATENATE(PROPER('DASMA INFO'!$G20),", ",PROPER('DASMA INFO'!$E20)," ",PROPER('DASMA INFO'!$F20),"."," (",UPPER('DASMA INFO'!$H20),")") -> Mata, Esteve . () | E20: ESTEVE | G20: MATA | I20: 0.05 | J20: 1000
A21: 21 | D21: =CONCATENATE(PROPER('DASMA INFO'!$G21),", ",PROPER('DASMA INFO'!$E21)," ",PROPER('DASMA INFO'!$F21),"."," (",UPPER('DASMA INFO'!$H21),")") -> Pandiño, Jocelyn . () | E21: JOCELYN | G21: PANDIÑO | I21: 0.05 | J21: 1000
A22: 22 | D22: =CONCATENATE(PROPER('DASMA INFO'!$G22),", ",PROPER('DASMA INFO'!$E22)," ",PROPER('DASMA INFO'!$F22),"."," (",UPPER('DASMA INFO'!$H22),")") -> Canaynay, Joy . () | E22: JOY | G22: CANAYNAY | I22: 0.05 | J22: 1000
A23: 23 | D23: =CONCATENATE(PROPER('DASMA INFO'!$G23),", ",PROPER('DASMA INFO'!$E23)," ",PROPER('DASMA INFO'!$F23),"."," (",UPPER('DASMA INFO'!$H23),")") -> Mabansag, Elizabeth . () | E23: ELIZABETH | G23: MABANSAG | I23: 0.05 | J23: 1000
A24: 24 | D24: =CONCATENATE(PROPER('DASMA INFO'!$G24),", ",PROPER('DASMA INFO'!$E24)," ",PROPER('DASMA INFO'!$F24),"."," (",UPPER('DASMA INFO'!$H24),")") -> Fornal, Jenefer . () | E24: JENEFER | G24: FORNAL | I24: 0.05 | J24: 1000 | K24: SSS ID, TIN ID
A25: 25 | D25: =CONCATENATE(PROPER('DASMA INFO'!$G25),", ",PROPER('DASMA INFO'!$E25)," ",PROPER('DASMA INFO'!$F25),"."," (",UPPER('DASMA INFO'!$H25),")") -> Cruz, Jennifer . () | E25: JENNIFER | G25: CRUZ | I25: 0.05 | J25: 1000
A26: 26 | D26: =CONCATENATE(PROPER('DASMA INFO'!$G26),", ",PROPER('DASMA INFO'!$E26)," ",PROPER('DASMA INFO'!$F26),"."," (",UPPER('DASMA INFO'!$H26),")") -> Benjamin, Jentaban . () | E26: JENTABAN | G26: BENJAMIN | I26: 0.05 | J26: 1000
A27: 27 | D27: =CONCATENATE(PROPER('DASMA INFO'!$G27),", ",PROPER('DASMA INFO'!$E27)," ",PROPER('DASMA INFO'!$F27),"."," (",UPPER('DASMA INFO'!$H27),")") -> Topacio, Birgita . () | E27: BIRGITA | G27: TOPACIO | I27: 0.05 | J27: 1000
A28: 28 | D28: =CONCATENATE(PROPER('DASMA INFO'!$G28),", ",PROPER('DASMA INFO'!$E28)," ",PROPER('DASMA INFO'!$F28),"."," (",UPPER('DASMA INFO'!$H28),")") -> Jentabal, Benjamin . () | E28: BENJAMIN | G28: JENTABAL | I28: 0.05 | J28: 1000
A29: 29 | D29: =CONCATENATE(PROPER('DASMA INFO'!$G29),", ",PROPER('DASMA INFO'!$E29)," ",PROPER('DASMA INFO'!$F29),"."," (",UPPER('DASMA INFO'!$H29),")") -> Cruz, Rolly B. () | E29: ROLLY | F29: B | G29: CRUZ | I29: 0.05 | J29: 2000 | K29: DRIVER'S LICENSE ID
A30: 30 | D30: =CONCATENATE(PROPER('DASMA INFO'!$G30),", ",PROPER('DASMA INFO'!$E30)," ",PROPER('DASMA INFO'!$F30),"."," (",UPPER('DASMA INFO'!$H30),")") -> Abella, Adolfo . () | E30: ADOLFO | G30: ABELLA | I30: 0.05 | J30: 1000
A31: 31 | D31: =CONCATENATE(PROPER('DASMA INFO'!$G31),", ",PROPER('DASMA INFO'!$E31)," ",PROPER('DASMA INFO'!$F31),"."," (",UPPER('DASMA INFO'!$H31),")") -> Mabansag, Lito . () | E31: LITO | G31: MABANSAG | I31: 0.05 | J31: 1000
A32: 32 | D32: =CONCATENATE(PROPER('DASMA INFO'!$G32),", ",PROPER('DASMA INFO'!$E32)," ",PROPER('DASMA INFO'!$F32),"."," (",UPPER('DASMA INFO'!$H32),")") -> Curioso, Emerson . () | E32: EMERSON | G32: CURIOSO | I32: 0.05 | J32: 1000
A33: 33 | D33: =CONCATENATE(PROPER('DASMA INFO'!$G33),", ",PROPER('DASMA INFO'!$E33)," ",PROPER('DASMA INFO'!$F33),"."," (",UPPER('DASMA INFO'!$H33),")") -> Ignacio, Sharon . () | E33: SHARON | G33: IGNACIO | I33: 0.05 | J33: 1000
A34: 34 | D34: =CONCATENATE(PROPER('DASMA INFO'!$G34),", ",PROPER('DASMA INFO'!$E34)," ",PROPER('DASMA INFO'!$F34),"."," (",UPPER('DASMA INFO'!$H34),")") -> Ibanez, Julie . () | E34: JULIE | G34: IBANEZ | I34: 0.05 | J34: 1000
A35: 35 | D35: =CONCATENATE(PROPER('DASMA INFO'!$G35),", ",PROPER('DASMA INFO'!$E35)," ",PROPER('DASMA INFO'!$F35),"."," (",UPPER('DASMA INFO'!$H35),")") -> Cheng, Alberto . () | E35: ALBERTO | G35: CHENG | I35: 0.05 | J35: 1000
A36: 36 | D36: =CONCATENATE(PROPER('DASMA INFO'!$G36),", ",PROPER('DASMA INFO'!$E36)," ",PROPER('DASMA INFO'!$F36),"."," (",UPPER('DASMA INFO'!$H36),")") -> Capili, Nenita . () | E36: NENITA | G36: CAPILI | I36: 0.05 | J36: 1000
A37: 37 | D37: =CONCATENATE(PROPER('DASMA INFO'!$G37),", ",PROPER('DASMA INFO'!$E37)," ",PROPER('DASMA INFO'!$F37),"."," (",UPPER('DASMA INFO'!$H37),")") -> , . () | I37: 0.05 | J37: 1000
A38: 38 | D38: =CONCATENATE(PROPER('DASMA INFO'!$G38),", ",PROPER('DASMA INFO'!$E38)," ",PROPER('DASMA INFO'!$F38),"."," (",UPPER('DASMA INFO'!$H38),")") -> Evangelio, Annalita Velasco. () | E38: ANNALITA | F38: VELASCO | G38: EVANGELIO | I38: 0.05 | J38: 1000
A39: 39 | D39: =CONCATENATE(PROPER('DASMA INFO'!$G39),", ",PROPER('DASMA INFO'!$E39)," ",PROPER('DASMA INFO'!$F39),"."," (",UPPER('DASMA INFO'!$H39),")") -> Espinas, Amor . () | E39: AMOR | G39: ESPINAS | I39: 0.05 | J39: 1000
A40: 40 | D40: =CONCATENATE(PROPER('DASMA INFO'!$G40),", ",PROPER('DASMA INFO'!$E40)," ",PROPER('DASMA INFO'!$F40),"."," (",UPPER('DASMA INFO'!$H40),")") -> Olaes, Marvin . () | E40: MARVIN | G40: OLAES | I40: 0.05 | J40: 1000
...

Sheet REGISTERED BIDDERS
B1: TOTAL NUMBER OF BIDDERS | C1: TOTAL No. OF ITEMS | D1: OVERALL TOTAL PRICE | F1: OVERALL SERVICE CHARGE | G1: OVERALL REGISTRATION FEE | H1: OVERALL GRAND TOTAL | I1: OVERALL MONITORING PRICE
B2: =COUNT('REGISTERED BIDDERS'!$B$5:$B$83) -> 40 | C2: =SUM('REGISTERED BIDDERS'!$C$5:$C$83) -> 0 | D2: =SUM('REGISTERED BIDDERS'!$D$5:$D$83) -> 0 | F2: =SUM('REGISTERED BIDDERS'!$F$5:$F$83) -> 0 | G2: =SUM('REGISTERED BIDDERS'!$G$5:$G$83) -> #N/A | H2: =SUM('REGISTERED BIDDERS'!$H$5:$H$83) -> #N/A | I2: =SUM('JANUARY 10, 2026'!$G$4:$G$1189) -> 0
A4: CNT | B4: BIDDER NO. | C4: NO. OF ITEMS | D4: TOTAL PRICE | E4: PERCENT | F4: SERVICE CHARGE | G4: REGISTRATION FEE | H4: GRAND TOTAL | I4: REMARKS PAID / DATE
B5: 4 | C5: =COUNTIF('JANUARY 10, 2026'!$A$4:$A$1189,'REGISTERED BIDDERS'!$B5) -> 0 | D5: =SUMIF('JANUARY 10, 2026'!$A$4:$A$1189,'REGISTERED BIDDERS'!$B5,'JANUARY 10, 2026'!$G$4:$G$1189) -> 0 | E5: =IFERROR(LOOKUP(B5,'NEW INFO'!$A$3:$A$1779,'NEW INFO'!$H$3:$H$1779),12%) -> 0.12 | F5: =D5*E5 -> 0 | G5: =IF(B5,LOOKUP(B5,'NEW INFO'!$A$3:$A$1779,'NEW INFO'!$I$3:$I$1779),"NA") -> #N/A | H5: =IF(G5>=(F5+D5),0,F5+D5-G5) -> #N/A
B6: 224 | C6: =COUNTIF('JANUARY 10, 2026'!$A$4:$A$1189,'REGISTERED BIDDERS'!$B6) -> 0 | D6: =SUMIF('JANUARY 10, 2026'!$A$4:$A$1189,'REGISTERED BIDDERS'!$B6,'JANUARY 10, 2026'!$G$4:$G$1189) -> 0 | E6: =IFERROR(LOOKUP(B6,'NEW INFO'!$A$3:$A$1779,'NEW INFO'!$H$3:$H$1779),12%) -> 0.12 | F6: =D6*E6 -> 0 | G6: =IF(B6,LOOKUP(B6,'NEW INFO'!$A$3:$A$1779,'NEW INFO'!$I$3:$I$1779),"NA") -> #N/A | H6: =IF(G6>=(F6+D6),0,F6+D6-G6) -> #N/A
B7: 270 | C7: =COUNTIF('JANUARY 10, 2026'!$A$4:$A$1189,'REGISTERED BIDDERS'!$B7) -> 0 | D7: =SUMIF('JANUARY 10, 2026'!$A$4:$A$1189,'REGISTERED BIDDERS'!$B7,'JANUARY 10, 2026'!$G$4:$G$1189) -> 0 | E7: =IFERROR(LOOKUP(B7,'NEW INFO'!$A$3:$A$1779,'NEW INFO'!$H$3:$H$1779),12%) -> 0.12 | F7: =D7*E7 -> 0 | G7: =IF(B7,LOOKUP(B7,'NEW INFO'!$A$3:$A$1779,'NEW INFO'!$I$3:$I$1779),"NA") -> #N/A | H7: =IF(G7>=(F7+D7),0,F7+D7-G7) -> #N/A
B8: 93 | C8: =COUNTIF('JANUARY 10, 2026'!$A$4:$A$1189,'REGISTERED BIDDERS'!$B8) -> 0 | D8: =SUMIF('JANUARY 10, 2026'!$A$4:$A$1189,'REGISTERED BIDDERS'!$B8,'JANUARY 10, 2026'!$G$4:$G$1189) -> 0 | E8: =IFERROR(LOOKUP(B8,'NEW INFO'!$A$3:$A$1779,'NEW INFO'!$H$3:$H$1779),12%) -> 0.12 | F8: =D8*E8 -> 0 | G8: =IF(B8,LOOKUP(B8,'NEW INFO'!$A$3:$A$1779,'NEW INFO'!$I$3:$I$1779),"NA") -> #N/A | H8: =IF(G8>=(F8+D8),0,F8+D8-G8) -> #N/A
B9: 15 | C9: =COUNTIF('JANUARY 10, 2026'!$A$4:$A$1189,'REGISTERED BIDDERS'!$B9) -> 0 | D9: =SUMIF('JANUARY 10, 2026'!$A$4:$A$1189,'REGISTERED BIDDERS'!$B9,'JANUARY 10, 2026'!$G$4:$G$1189) -> 0 | E9: =IFERROR(LOOKUP(B9,'NEW INFO'!$A$3:$A$1779,'NEW INFO'!$H$3:$H$1779),12%) -> 0.12 | F9: =D9*E9 -> 0 | G9: =IF(B9,LOOKUP(B9,'NEW INFO'!$A$3:$A$1779,'NEW INFO'!$I$3:$I$1779),"NA") -> #N/A | H9: =IF(G9>=(F9+D9),0,F9+D9-G9) -> #N/A
B10: 39 | C10: =COUNTIF('JANUARY 10, 2026'!$A$4:$A$1189,'REGISTERED BIDDERS'!$B10) -> 0 | D10: =SUMIF('JANUARY 10, 2026'!$A$4:$A$1189,'REGISTERED BIDDERS'!$B10,'JANUARY 10, 2026'!$G$4:$G$1189) -> 0 | E10: =IFERROR(LOOKUP(B10,'NEW INFO'!$A$3:$A$1779,'NEW INFO'!$H$3:$H$1779),12%) -> 0.12 | F10: =D10*E10 -> 0 | G10: =IF(B10,LOOKUP(B10,'NEW INFO'!$A$3:$A$1779,'NEW INFO'!$I$3:$I$1779),"NA") -> #N/A | H10: =IF(G10>=(F10+D10),0,F10+D10-G10) -> #N/A
B11: 1081 | C11: =COUNTIF('JANUARY 10, 2026'!$A$4:$A$1189,'REGISTERED BIDDERS'!$B11) -> 0 | D11: =SUMIF('JANUARY 10, 2026'!$A$4:$A$1189,'REGISTERED BIDDERS'!$B11,'JANUARY 10, 2026'!$G$4:$G$1189) -> 0 | E11: =IFERROR(LOOKUP(B11,'NEW INFO'!$A$3:$A$1779,'NEW INFO'!$H$3:$H$1779),12%) -> 0.12 | F11: =D11*E11 -> 0 | G11: =IF(B11,LOOKUP(B11,'NEW INFO'!$A$3:$A$1779,'NEW INFO'!$I$3:$I$1779),"NA") -> #N/A | H11: =IF(G11>=(F11+D11),0,F11+D11-G11) -> #N/A
B12: 1378 | C12: =COUNTIF('JANUARY 10, 2026'!$A$4:$A$1189,'REGISTERED BIDDERS'!$B12) -> 0 | D12: =SUMIF('JANUARY 10, 2026'!$A$4:$A$1189,'REGISTERED BIDDERS'!$B12,'JANUARY 10, 2026'!$G$4:$G$1189) -> 0 | E12: =IFERROR(LOOKUP(B12,'NEW INFO'!$A$3:$A$1779,'NEW INFO'!$H$3:$H$1779),12%) -> 0.12 | F12: =D12*E12 -> 0 | G12: =IF(B12,LOOKUP(B12,'NEW INFO'!$A$3:$A$1779,'NEW INFO'!$I$3:$I$1779),"NA") -> #N/A | H12: =IF(G12>=(F12+D12),0,F12+D12-G12) -> #N/A
B13: 1155 | C13: =COUNTIF('JANUARY 10, 2026'!$A$4:$A$1189,'REGISTERED BIDDERS'!$B13) -> 0 | D13: =SUMIF('JANUARY 10, 2026'!$A$4:$A$1189,'REGISTERED BIDDERS'!$B13,'JANUARY 10, 2026'!$G$4:$G$1189) -> 0 | E13: =IFERROR(LOOKUP(B13,'NEW INFO'!$A$3:$A$1779,'NEW INFO'!$H$3:$H$1779),12%) -> 0.12 | F13: =D13*E13 -> 0 | G13: =IF(B13,LOOKUP(B13,'NEW INFO'!$A$3:$A$1779,'NEW INFO'!$I$3:$I$1779),"NA") -> #N/A | H13: =IF(G13>=(F13+D13),0,F13+D13-G13) -> #N/A
B14: 1101 | C14: =COUNTIF('JANUARY 10, 2026'!$A$4:$A$1189,'REGISTERED BIDDERS'!$B14) -> 0 | D14: =SUMIF('JANUARY 10, 2026'!$A$4:$A$1189,'REGISTERED BIDDERS'!$B14,'JANUARY 10, 2026'!$G$4:$G$1189) -> 0 | E14: =IFERROR(LOOKUP(B14,'NEW INFO'!$A$3:$A$1779,'NEW INFO'!$H$3:$H$1779),12%) -> 0.12 | F14: =D14*E14 -> 0 | G14: =IF(B14,LOOKUP(B14,'NEW INFO'!$A$3:$A$1779,'NEW INFO'!$I$3:$I$1779),"NA") -> #N/A | H14: =IF(G14>=(F14+D14),0,F14+D14-G14) -> #N/A
B15: 2 | C15: =COUNTIF('JANUARY 10, 2026'!$A$4:$A$1189,'REGISTERED BIDDERS'!$B15) -> 0 | D15: =SUMIF('JANUARY 10, 2026'!$A$4:$A$1189,'REGISTERED BIDDERS'!$B15,'JANUARY 10, 2026'!$G$4:$G$1189) -> 0 | E15: =IFERROR(LOOKUP(B15,'NEW INFO'!$A$3:$A$1779,'NEW INFO'!$H$3:$H$1779),12%) -> 0.12 | F15: =D15*E15 -> 0 | G15: =IF(B15,LOOKUP(B15,'NEW INFO'!$A$3:$A$1779,'NEW INFO'!$I$3:$I$1779),"NA") -> #N/A | H15: =IF(G15>=(F15+D15),0,F15+D15-G15) -> #N/A
B16: 203 | C16: =COUNTIF('JANUARY 10, 2026'!$A$4:$A$1189,'REGISTERED BIDDERS'!$B16) -> 0 | D16: =SUMIF('JANUARY 10, 2026'!$A$4:$A$1189,'REGISTERED BIDDERS'!$B16,'JANUARY 10, 2026'!$G$4:$G$1189) -> 0 | E16: =IFERROR(LOOKUP(B16,'NEW INFO'!$A$3:$A$1779,'NEW INFO'!$H$3:$H$1779),12%) -> 0.12 | F16: =D16*E16 -> 0 | G16: =IF(B16,LOOKUP(B16,'NEW INFO'!$A$3:$A$1779,'NEW INFO'!$I$3:$I$1779),"NA") -> #N/A | H16: =IF(G16>=(F16+D16),0,F16+D16-G16) -> #N/A
... B44: 1412 | C44: =COUNTIF('JANUARY 10, 2026'!$A$4:$A$1189,'REGISTERED BIDDERS'!$B44) -> 0 | D44: =SUMIF('JANUARY 10, 2026'!$A$4:$A$1189,'REGISTERED BIDDERS'!$B44,'JANUARY 10, 2026'!$G$4:$G$1189) -> 0 | E44: =IFERROR(LOOKUP(B44,'NEW INFO'!$A$3:$A$1779,'NEW INFO'!$H$3:$H$1779),12%) -> 0.12 | F44: =D44*E44 -> 0 | G44: =IF(B44,LOOKUP(B44,'NEW INFO'!$A$3:$A$1779,'NEW INFO'!$I$3:$I$1779),"NA") -> #N/A | H44: =IF(G44>=(F44+D44),0,F44+D44-G44) -> #N/A
C45: =COUNTIF('JANUARY 10, 2026'!$A$4:$A$1189,'REGISTERED BIDDERS'!$B45) -> 0 | D45: =SUMIF('JANUARY 10, 2026'!$A$4:$A$1189,'REGISTERED BIDDERS'!$B45,'JANUARY 10, 2026'!$G$4:$G$1189) -> 0 | E45: =IFERROR(LOOKUP(B45,'NEW INFO'!$A$3:$A$1779,'NEW INFO'!$H$3:$H$1779),12%) -> 0.12 | F45: =D45*E45 -> 0 | G45: =IF(B45,LOOKUP(B45,'NEW INFO'!$A$3:$A$1779,'NEW INFO'!$I$3:$I$1779),"NA") -> NA | H45: =IF(G45>=(F45+D45),0,F45+D45-G45) -> 0
C46: =COUNTIF('JANUARY 10, 2026'!$A$4:$A$1189,'REGISTERED BIDDERS'!$B46) -> 0 | D46: =SUMIF('JANUARY 10, 2026'!$A$4:$A$1189,'REGISTERED BIDDERS'!$B46,'JANUARY 10, 2026'!$G$4:$G$1189) -> 0 | E46: =IFERROR(LOOKUP(B46,'NEW INFO'!$A$3:$A$1779,'NEW INFO'!$H$3:$H$1779),12%) -> 0.12 | F46: =D46*E46 -> 0 | G46: =IF(B46,LOOKUP(B46,'NEW INFO'!$A$3:$A$1779,'NEW INFO'!$I$3:$I$1779),"NA") -> NA | H46: =IF(G46>=(F46+D46),0,F46+D46-G46) -> 0
C47: =COUNTIF('JANUARY 10, 2026'!$A$4:$A$1189,'REGISTERED BIDDERS'!$B47) -> 0 | D47: =SUMIF('JANUARY 10, 2026'!$A$4:$A$1189,'REGISTERED BIDDERS'!$B47,'JANUARY 10, 2026'!$G$4:$G$1189) -> 0 | E47: =IFERROR(LOOKUP(B47,'NEW INFO'!$A$3:$A$1779,'NEW INFO'!$H$3:$H$1779),12%) -> 0.12 | F47: =D47*E47 -> 0 | G47: =IF(B47,LOOKUP(B47,'NEW INFO'!$A$3:$A$1779,'NEW INFO'!$I$3:$I$1779),"NA") -> NA | H47: =IF(G47>=(F47+D47),0,F47+D47-G47) -> 0
C48: =COUNTIF('JANUARY 10, 2026'!$A$4:$A$1189,'REGISTERED BIDDERS'!$B48) -> 0 | D48: =SUMIF('JANUARY 10, 2026'!$A$4:$A$1189,'REGISTERED BIDDERS'!$B48,'JANUARY 10, 2026'!$G$4:$G$1189) -> 0 | E48: =IFERROR(LOOKUP(B48,'NEW INFO'!$A$3:$A$1779,'NEW INFO'!$H$3:$H$1779),12%) -> 0.12 | F48: =D48*E48 -> 0 | G48: =IF(B48,LOOKUP(B48,'NEW INFO'!$A$3:$A$1779,'NEW INFO'!$I$3:$I$1779),"NA") -> NA | H48: =IF(G48>=(F48+D48),0,F48+D48-G48) -> 0
C49: =COUNTIF('JANUARY 10, 2026'!$A$4:$A$1189,'REGISTERED BIDDERS'!$B49) -> 0 | D49: =SUMIF('JANUARY 10, 2026'!$A$4:$A$1189,'REGISTERED BIDDERS'!$B49,'JANUARY 10, 2026'!$G$4:$G$1189) -> 0 | E49: =IFERROR(LOOKUP(B49,'NEW INFO'!$A$3:$A$1779,'NEW INFO'!$H$3:$H$1779),12%) -> 0.12 | F49: =D49*E49 -> 0 | G49: =IF(B49,LOOKUP(B49,'NEW INFO'!$A$3:$A$1779,'NEW INFO'!$I$3:$I$1779),"NA") -> NA | H49: =IF(G49>=(F49+D49),0,F49+D49-G49) -> 0
C50: =COUNTIF('JANUARY 10, 2026'!$A$4:$A$1189,'REGISTERED BIDDERS'!$B50) -> 0 | D50: =SUMIF('JANUARY 10, 2026'!$A$4:$A$1189,'REGISTERED BIDDERS'!$B50,'JANUARY 10, 2026'!$G$4:$G$1189) -> 0 | E50: =IFERROR(LOOKUP(B50,'NEW INFO'!$A$3:$A$1779,'NEW INFO'!$H$3:$H$1779),12%) -> 0.12 | F50: =D50*E50 -> 0 | G50: =IF(B50,LOOKUP(B50,'NEW INFO'!$A$3:$A$1779,'NEW INFO'!$I$3:$I$1779),"NA") -> NA | H50: =IF(G50>=(F50+D50),0,F50+D50-G50) -> 0
C51: =COUNTIF('JANUARY 10, 2026'!$A$4:$A$1189,'REGISTERED BIDDERS'!$B51) -> 0 | D51: =SUMIF('JANUARY 10, 2026'!$A$4:$A$1189,'REGISTERED BIDDERS'!$B51,'JANUARY 10, 2026'!$G$4:$G$1189) -> 0 | E51: =IFERROR(LOOKUP(B51,'NEW INFO'!$A$3:$A$1779,'NEW INFO'!$H$3:$H$1779),12%) -> 0.12 | F51: =D51*E51 -> 0 | G51: =IF(B51,LOOKUP(B51,'NEW INFO'!$A$3:$A$1779,'NEW INFO'!$I$3:$I$1779),"NA") -> NA | H51: =IF(G51>=(F51+D51),0,F51+D51-G51) -> 0
C52: =COUNTIF('JANUARY 10, 2026'!$A$4:$A$1189,'REGISTERED BIDDERS'!$B52) -> 0 | D52: =SUMIF('JANUARY 10, 2026'!$A$4:$A$1189,'REGISTERED BIDDERS'!$B52,'JANUARY 10, 2026'!$G$4:$G$1189) -> 0 | E52: =IFERROR(LOOKUP(B52,'NEW INFO'!$A$3:$A$1779,'NEW INFO'!$H$3:$H$1779),12%) -> 0.12 | F52: =D52*E52 -> 0 | G52: =IF(B52,LOOKUP(B52,'NEW INFO'!$A$3:$A$1779,'NEW INFO'!$I$3:$I$1779),"NA") -> NA | H52: =IF(G52>=(F52+D52),0,F52+D52-G52) -> 0
C53: =COUNTIF('JANUARY 10, 2026'!$A$4:$A$1189,'REGISTERED BIDDERS'!$B53) -> 0 | D53: =SUMIF('JANUARY 10, 2026'!$A$4:$A$1189,'REGISTERED BIDDERS'!$B53,'JANUARY 10, 2026'!$G$4:$G$1189) -> 0 | E53: =IFERROR(LOOKUP(B53,'NEW INFO'!$A$3:$A$1779,'NEW INFO'!$H$3:$H$1779),12%) -> 0.12 | F53: =D53*E53 -> 0 | G53: =IF(B53,LOOKUP(B53,'NEW INFO'!$A$3:$A$1779,'NEW INFO'!$I$3:$I$1779),"NA") -> NA | H53: =IF(G53>=(F53+D53),0,F53+D53-G53) -> 0
C54: =COUNTIF('JANUARY 10, 2026'!$A$4:$A$1189,'REGISTERED BIDDERS'!$B54) -> 0 | D54: =SUMIF('JANUARY 10, 2026'!$A$4:$A$1189,'REGISTERED BIDDERS'!$B54,'JANUARY 10, 2026'!$G$4:$G$1189) -> 0 | E54: =IFERROR(LOOKUP(B54,'NEW INFO'!$A$3:$A$1779,'NEW INFO'!$H$3:$H$1779),12%) -> 0.12 | F54: =D54*E54 -> 0 | G54: =IF(B54,LOOKUP(B54,'NEW INFO'!$A$3:$A$1779,'NEW INFO'!$I$3:$I$1779),"NA") -> NA | H54: =IF(G54>=(F54+D54),0,F54+D54-G54) -> 0
C55: =COUNTIF('JANUARY 10, 2026'!$A$4:$A$1189,'REGISTERED BIDDERS'!$B55) -> 0 | D55: =SUMIF('JANUARY 10, 2026'!$A$4:$A$1189,'REGISTERED BIDDERS'!$B55,'JANUARY 10, 2026'!$G$4:$G$1189) -> 0 | E55: =IFERROR(LOOKUP(B55,'NEW INFO'!$A$3:$A$1779,'NEW INFO'!$H$3:$H$1779),12%) -> 0.12 | F55: =D55*E55 -> 0 | G55: =IF(B55,LOOKUP(B55,'NEW INFO'!$A$3:$A$1779,'NEW INFO'!$I$3:$I$1779),"NA") -> NA | H55: =IF(G55>=(F55+D55),0,F55+D55-G55) -> 0
C56: =COUNTIF('JANUARY 10, 2026'!$A$4:$A$1189,'REGISTERED BIDDERS'!$B56) -> 0 | D56: =SUMIF('JANUARY 10, 2026'!$A$4:$A$1189,'REGISTERED BIDDERS'!$B56,'JANUARY 10, 2026'!$G$4:$G$1189) -> 0 | E56: =IFERROR(LOOKUP(B56,'NEW INFO'!$A$3:$A$1779,'NEW INFO'!$H$3:$H$1779),12%) -> 0.12 | F56: =D56*E56 -> 0 | G56: =IF(B56,LOOKUP(B56,'NEW INFO'!$A$3:$A$1779,'NEW INFO'!$I$3:$I$1779),"NA") -> NA | H56: =IF(G56>=(F56+D56),0,F56+D56-G56) -> 0
... C83: =COUNTIF('JANUARY 10, 2026'!$A$4:$A$1189,'REGISTERED BIDDERS'!$B83) -> 0 | D83: =SUMIF('JANUARY 10, 2026'!$A$4:$A$1189,'REGISTERED BIDDERS'!$B83,'JANUARY 10, 2026'!$G$4:$G$1189) -> 0 | E83: =IFERROR(LOOKUP(B83,'NEW INFO'!$A$3:$A$1779,'NEW INFO'!$H$3:$H$1779),12%) -> 0.12 | F83: =D83*E83 -> 0 | G83: =IF(B83,LOOKUP(B83,'NEW INFO'!$A$3:$A$1779,'NEW INFO'!$I$3:$I$1779),"NA") -> NA | H83: =IF(G83>=(F83+D83),0,F83+D83-G83) -> 0

Sheet 5%
A1: BIDDER # 5% | B1: Column1 | C1: REMARKS
A2: 692 | B2: 0.05
A3: 694 | B3: 0.05
A4: 697 | B4: 0.05 | C4: DTI
A5: 698 | B5: 0.05
A6: 700 | B6: 0.05
A7: 703 | B7: 0.05
A8: 728 | B8: 0.05
A9: 732 | B9: 0.05
A10: 733 | B10: 0.05
A11: 734 | B11: 0.05
A12: 747 | B12: 0.05
A13: 749 | B13: 0.05
A14: 753 | B14: 0.05
A15: 755 | B15: 0.05
A16: 761 | B16: 0.05
... A20: 786 | B20: 0.05
A21: 788 | B21: 0.05 | C21: DTI 08-18-2016
A22: 800 | B22: 0.05
A23: 808 | B23: 0.05
A24: 820 | B24: 0.05
A25: 824 | B25: 0.05
A26: 825 | B26: 0.05
A27: 830 | B27: 0.05
A28: 846 | B28: 0.05
A29: 852 | B29: 0.05
A30: 853 | B30: 0.05
A31: 860 | B31: 0.05
A32: 865 | B32: 0.05
A33: 866 | B33: 0.05
... A70: 1053 | B70: 0.05
A71: 1054 | B71: 0.05 | C71: APPROVED BY TITA EMIE 04-14-16
A72: 1061 | B72: 0.05
A73: 1068 | B73: 0.05
A74: 1071 | B74: 0.05
A75: 1074 | B75: 0.05
A76: 1077 | B76: 0.05
A77: 1086 | B77: 0.05
A78: 1109 | B78: 0.05
A79: 1112 | B79: 0.05
...
